Workbook

Sheet Concentrado
A1: CONCENTRADO DE VENTAS POR TIENDA — FEBRERO A SEPTIEMBRE 2026
A2: Venta en pesos (MXN). Cada tienda suma lo vendido en BMS Julio Alejandro + BMS Procortes, para que la migración no corte la serie.
A4: Sucursal | B4: Migración a Procortes | C4: Feb-26 | D4: Mar-26 | E4: Abr-26 | F4: May-26 | G4: Jun-26 | H4: Jul-26 | I4: Ago-26 | J4: Sep-26 | K4: Total 8 meses | L4: Promedio mensual | M4: Var. Sep vs Feb
A5: Av. México | B5: 17-ago-2026 | C5: =SUMIFS('Captura BMS'!$C$1:$C$200,'Captura BMS'!$A$1:$A$200,$A5,'Captura BMS'!$B$1:$B$200,"Julio Alejandro")+SUMIFS('Captura BMS'!$C$1:$C$200,'Captura BMS'!$A$1:$A$200,$A5,'Captura BMS'!$B$1:$B$200,"Procortes") | D5: =SUMIFS('Captura BMS'!$D$1:$D$200,'Captura BMS'!$A$1:$A$200,$A5,'Captura BMS'!$B$1:$B$200,"Julio Alejandro")+SUMIFS('Captura BMS'!$D$1:$D$200,'Captura BMS'!$A$1:$A$200,$A5,'Captura BMS'!$B$1:$B$200,"Procortes") | E5: =SUMIFS('Captura BMS'!$E$1:$E$200,'Captura BMS'!$A$1:$A$200,$A5,'Captura BMS'!$B$1:$B$200,"Julio Alejandro")+SUMIFS('Captura BMS'!$E$1:$E$200,'Captura BMS'!$A$1:$A$200,$A5,'Captura BMS'!$B$1:$B$200,"Procortes") | F5: =SUMIFS('Captura BMS'!$F$1:$F$200,'Captura BMS'!$A$1:$A$200,$A5,'Captura BMS'!$B$1:$B$200,"Julio Alejandro")+SUMIFS('Captura BMS'!$F$1:$F$200,'Captura BMS'!$A$1:$A$200,$A5,'Captura BMS'!$B$1:$B$200,"Procortes") | G5: =SUMIFS('Captura BMS'!$G$1:$G$200,'Captura BMS'!$A$1:$A$200,$A5,'Captura BMS'!$B$1:$B$200,"Julio Alejandro")+SUMIFS('Captura BMS'!$G$1:$G$200,'Captura BMS'!$A$1:$A$200,$A5,'Captura BMS'!$B$1:$B$200,"Procortes") | H5: =SUMIFS('Captura BMS'!$H$1:$H$200,'Captura BMS'!$A$1:$A$200,$A5,'Captura BMS'!$B$1:$B$200,"Julio Alejandro")+SUMIFS('Captura BMS'!$H$1:$H$200,'Captura BMS'!$A$1:$A$200,$A5,'Captura BMS'!$B$1:$B$200,"Procortes") | I5: =SUMIFS('Captura BMS'!$I$1:$I$200,'Captura BMS'!$A$1:$A$200,$A5,'Captura BMS'!$B$1:$B$200,"Julio Alejandro")+SUMIFS('Captura BMS'!$I$1:$I$200,'Captura BMS'!$A$1:$A$200,$A5,'Captura BMS'!$B$1:$B$200,"Procortes") | J5: =SUMIFS('Captura BMS'!$J$1:$J$200,'Captura BMS'!$A$1:$A$200,$A5,'Captura BMS'!$B$1:$B$200,"Julio Alejandro")+SUMIFS('Captura BMS'!$J$1:$J$200,'Captura BMS'!$A$1:$A$200,$A5,'Captura BMS'!$B$1:$B$200,"Procortes") | K5: =SUM(C5:J5) | L5: =IFERROR(AVERAGEIF(C5:J5,">0"),0) | M5: =IF(OR(C5=0,J5=0),"",J5/C5-1)
A6: Bucerías | B6: 07-sep-2026 | C6: =SUMIFS('Captura BMS'!$C$1:$C$200,'Captura BMS'!$A$1:$A$200,$A6,'Captura BMS'!$B$1:$B$200,"Julio Alejandro")+SUMIFS('Captura BMS'!$C$1:$C$200,'Captura BMS'!$A$1:$A$200,$A6,'Captura BMS'!$B$1:$B$200,"Procortes") | D6: =SUMIFS('Captura BMS'!$D$1:$D$200,'Captura BMS'!$A$1:$A$200,$A6,'Captura BMS'!$B$1:$B$200,"Julio Alejandro")+SUMIFS('Captura BMS'!$D$1:$D$200,'Captura BMS'!$A$1:$A$200,$A6,'Captura BMS'!$B$1:$B$200,"Procortes") | E6: =SUMIFS('Captura BMS'!$E$1:$E$200,'Captura BMS'!$A$1:$A$200,$A6,'Captura BMS'!$B$1:$B$200,"Julio Alejandro")+SUMIFS('Captura BMS'!$E$1:$E$200,'Captura BMS'!$A$1:$A$200,$A6,'Captura BMS'!$B$1:$B$200,"Procortes") | F6: =SUMIFS('Captura BMS'!$F$1:$F$200,'Captura BMS'!$A$1:$A$200,$A6,'Captura BMS'!$B$1:$B$200,"Julio Alejandro")+SUMIFS('Captura BMS'!$F$1:$F$200,'Captura BMS'!$A$1:$A$200,$A6,'Captura BMS'!$B$1:$B$200,"Procortes") | G6: =SUMIFS('Captura BMS'!$G$1:$G$200,'Captura BMS'!$A$1:$A$200,$A6,'Captura BMS'!$B$1:$B$200,"Julio Alejandro")+SUMIFS('Captura BMS'!$G$1:$G$200,'Captura BMS'!$A$1:$A$200,$A6,'Captura BMS'!$B$1:$B$200,"Procortes") | H6: =SUMIFS('Captura BMS'!$H$1:$H$200,'Captura BMS'!$A$1:$A$200,$A6,'Captura BMS'!$B$1:$B$200,"Julio Alejandro")+SUMIFS('Captura BMS'!$H$1:$H$200,'Captura BMS'!$A$1:$A$200,$A6,'Captura BMS'!$B$1:$B$200,"Procortes") | I6: =SUMIFS('Captura BMS'!$I$1:$I$200,'Captura BMS'!$A$1:$A$200,$A6,'Captura BMS'!$B$1:$B$200,"Julio Alejandro")+SUMIFS('Captura BMS'!$I$1:$I$200,'Captura BMS'!$A$1:$A$200,$A6,'Captura BMS'!$B$1:$B$200,"Procortes") | J6: =SUMIFS('Captura BMS'!$J$1:$J$200,'Captura BMS'!$A$1:$A$200,$A6,'Captura BMS'!$B$1:$B$200,"Julio Alejandro")+SUMIFS('Captura BMS'!$J$1:$J$200,'Captura BMS'!$A$1:$A$200,$A6,'Captura BMS'!$B$1:$B$200,"Procortes") | K6: =SUM(C6:J6) | L6: =IFERROR(AVERAGEIF(C6:J6,">0"),0) | M6: =IF(OR(C6=0,J6=0),"",J6/C6-1)
A7: Cantera | B7: 27-jul-2026 | C7: =SUMIFS('Captura BMS'!$C$1:$C$200,'Captura BMS'!$A$1:$A$200,$A7,'Captura BMS'!$B$1:$B$200,"Julio Alejandro")+SUMIFS('Captura BMS'!$C$1:$C$200,'Captura BMS'!$A$1:$A$200,$A7,'Captura BMS'!$B$1:$B$200,"Procortes") | D7: =SUMIFS('Captura BMS'!$D$1:$D$200,'Captura BMS'!$A$1:$A$200,$A7,'Captura BMS'!$B$1:$B$200,"Julio Alejandro")+SUMIFS('Captura BMS'!$D$1:$D$200,'Captura BMS'!$A$1:$A$200,$A7,'Captura BMS'!$B$1:$B$200,"Procortes") | E7: =SUMIFS('Captura BMS'!$E$1:$E$200,'Captura BMS'!$A$1:$A$200,$A7,'Captura BMS'!$B$1:$B$200,"Julio Alejandro")+SUMIFS('Captura BMS'!$E$1:$E$200,'Captura BMS'!$A$1:$A$200,$A7,'Captura BMS'!$B$1:$B$200,"Procortes") | F7: =SUMIFS('Captura BMS'!$F$1:$F$200,'Captura BMS'!$A$1:$A$200,$A7,'Captura BMS'!$B$1:$B$200,"Julio Alejandro")+SUMIFS('Captura BMS'!$F$1:$F$200,'Captura BMS'!$A$1:$A$200,$A7,'Captura BMS'!$B$1:$B$200,"Procortes") | G7: =SUMIFS('Captura BMS'!$G$1:$G$200,'Captura BMS'!$A$1:$A$200,$A7,'Captura BMS'!$B$1:$B$200,"Julio Alejandro")+SUMIFS('Captura BMS'!$G$1:$G$200,'Captura BMS'!$A$1:$A$200,$A7,'Captura BMS'!$B$1:$B$200,"Procortes") | H7: =SUMIFS('Captura BMS'!$H$1:$H$200,'Captura BMS'!$A$1:$A$200,$A7,'Captura BMS'!$B$1:$B$200,"Julio Alejandro")+SUMIFS('Captura BMS'!$H$1:$H$200,'Captura BMS'!$A$1:$A$200,$A7,'Captura BMS'!$B$1:$B$200,"Procortes") | I7: =SUMIFS('Captura BMS'!$I$1:$I$200,'Captura BMS'!$A$1:$A$200,$A7,'Captura BMS'!$B$1:$B$200,"Julio Alejandro")+SUMIFS('Captura BMS'!$I$1:$I$200,'Captura BMS'!$A$1:$A$200,$A7,'Captura BMS'!$B$1:$B$200,"Procortes") | J7: =SUMIFS('Captura BMS'!$J$1:$J$200,'Captura BMS'!$A$1:$A$200,$A7,'Captura BMS'!$B$1:$B$200,"Julio Alejandro")+SUMIFS('Captura BMS'!$J$1:$J$200,'Captura BMS'!$A$1:$A$200,$A7,'Captura BMS'!$B$1:$B$200,"Procortes") | K7: =SUM(C7:J7) | L7: =IFERROR(AVERAGEIF(C7:J7,">0"),0) | M7: =IF(OR(C7=0,J7=0),"",J7/C7-1)
A8: Ejido | B8: 10-ago-2026 | C8: =SUMIFS('Captura BMS'!$C$1:$C$200,'Captura BMS'!$A$1:$A$200,$A8,'Captura BMS'!$B$1:$B$200,"Julio Alejandro")+SUMIFS('Captura BMS'!$C$1:$C$200,'Captura BMS'!$A$1:$A$200,$A8,'Captura BMS'!$B$1:$B$200,"Procortes") | D8: =SUMIFS('Captura BMS'!$D$1:$D$200,'Captura BMS'!$A$1:$A$200,$A8,'Captura BMS'!$B$1:$B$200,"Julio Alejandro")+SUMIFS('Captura BMS'!$D$1:$D$200,'Captura BMS'!$A$1:$A$200,$A8,'Captura BMS'!$B$1:$B$200,"Procortes") | E8: =SUMIFS('Captura BMS'!$E$1:$E$200,'Captura BMS'!$A$1:$A$200,$A8,'Captura BMS'!$B$1:$B$200,"Julio Alejandro")+SUMIFS('Captura BMS'!$E$1:$E$200,'Captura BMS'!$A$1:$A$200,$A8,'Captura BMS'!$B$1:$B$200,"Procortes") | F8: =SUMIFS('Captura BMS'!$F$1:$F$200,'Captura BMS'!$A$1:$A$200,$A8,'Captura BMS'!$B$1:$B$200,"Julio Alejandro")+SUMIFS('Captura BMS'!$F$1:$F$200,'Captura BMS'!$A$1:$A$200,$A8,'Captura BMS'!$B$1:$B$200,"Procortes") | G8: =SUMIFS('Captura BMS'!$G$1:$G$200,'Captura BMS'!$A$1:$A$200,$A8,'Captura BMS'!$B$1:$B$200,"Julio Alejandro")+SUMIFS('Captura BMS'!$G$1:$G$200,'Captura BMS'!$A$1:$A$200,$A8,'Captura BMS'!$B$1:$B$200,"Procortes") | H8: =SUMIFS('Captura BMS'!$H$1:$H$200,'Captura BMS'!$A$1:$A$200,$A8,'Captura BMS'!$B$1:$B$200,"Julio Alejandro")+SUMIFS('Captura BMS'!$H$1:$H$200,'Captura BMS'!$A$1:$A$200,$A8,'Captura BMS'!$B$1:$B$200,"Procortes") | I8: =SUMIFS('Captura BMS'!$I$1:$I$200,'Captura BMS'!$A$1:$A$200,$A8,'Captura BMS'!$B$1:$B$200,"Julio Alejandro")+SUMIFS('Captura BMS'!$I$1:$I$200,'Captura BMS'!$A$1:$A$200,$A8,'Captura BMS'!$B$1:$B$200,"Procortes") | J8: =SUMIFS('Captura BMS'!$J$1:$J$200,'Captura BMS'!$A$1:$A$200,$A8,'Captura BMS'!$B$1:$B$200,"Julio Alejandro")+SUMIFS('Captura BMS'!$J$1:$J$200,'Captura BMS'!$A$1:$A$200,$A8,'Captura BMS'!$B$1:$B$200,"Procortes") | K8: =SUM(C8:J8) | L8: =IFERROR(AVERAGEIF(C8:J8,">0"),0) | M8: =IF(OR(C8=0,J8=0),"",J8/C8-1)
A9: Fluvial | B9: — | C9: =SUMIFS('Captura BMS'!$C$1:$C$200,'Captura BMS'!$A$1:$A$200,$A9,'Captura BMS'!$B$1:$B$200,"Julio Alejandro")+SUMIFS('Captura BMS'!$C$1:$C$200,'Captura BMS'!$A$1:$A$200,$A9,'Captura BMS'!$B$1:$B$200,"Procortes") | D9: =SUMIFS('Captura BMS'!$D$1:$D$200,'Captura BMS'!$A$1:$A$200,$A9,'Captura BMS'!$B$1:$B$200,"Julio Alejandro")+SUMIFS('Captura BMS'!$D$1:$D$200,'Captura BMS'!$A$1:$A$200,$A9,'Captura BMS'!$B$1:$B$200,"Procortes") | E9: =SUMIFS('Captura BMS'!$E$1:$E$200,'Captura BMS'!$A$1:$A$200,$A9,'Captura BMS'!$B$1:$B$200,"Julio Alejandro")+SUMIFS('Captura BMS'!$E$1:$E$200,'Captura BMS'!$A$1:$A$200,$A9,'Captura BMS'!$B$1:$B$200,"Procortes") | F9: =SUMIFS('Captura BMS'!$F$1:$F$200,'Captura BMS'!$A$1:$A$200,$A9,'Captura BMS'!$B$1:$B$200,"Julio Alejandro")+SUMIFS('Captura BMS'!$F$1:$F$200,'Captura BMS'!$A$1:$A$200,$A9,'Captura BMS'!$B$1:$B$200,"Procortes") | G9: =SUMIFS('Captura BMS'!$G$1:$G$200,'Captura BMS'!$A$1:$A$200,$A9,'Captura BMS'!$B$1:$B$200,"Julio Alejandro")+SUMIFS('Captura BMS'!$G$1:$G$200,'Captura BMS'!$A$1:$A$200,$A9,'Captura BMS'!$B$1:$B$200,"Procortes") | H9: =SUMIFS('Captura BMS'!$H$1:$H$200,'Captura BMS'!$A$1:$A$200,$A9,'Captura BMS'!$B$1:$B$200,"Julio Alejandro")+SUMIFS('Captura BMS'!$H$1:$H$200,'Captura BMS'!$A$1:$A$200,$A9,'Captura BMS'!$B$1:$B$200,"Procortes") | I9: =SUMIFS('Captura BMS'!$I$1:$I$200,'Captura BMS'!$A$1:$A$200,$A9,'Captura BMS'!$B$1:$B$200,"Julio Alejandro")+SUMIFS('Captura BMS'!$I$1:$I$200,'Captura BMS'!$A$1:$A$200,$A9,'Captura BMS'!$B$1:$B$200,"Procortes") | J9: =SUMIFS('Captura BMS'!$J$1:$J$200,'Captura BMS'!$A$1:$A$200,$A9,'Captura BMS'!$B$1:$B$200,"Julio Alejandro")+SUMIFS('Captura BMS'!$J$1:$J$200,'Captura BMS'!$A$1:$A$200,$A9,'Captura BMS'!$B$1:$B$200,"Procortes") | K9: =SUM(C9:J9) | L9: =IFERROR(AVERAGEIF(C9:J9,">0"),0) | M9: =IF(OR(C9=0,J9=0),"",J9/C9-1)
A10: Insurgentes | B10: abr-2026 | C10: =SUMIFS('Captura BMS'!$C$1:$C$200,'Captura BMS'!$A$1:$A$200,$A10,'Captura BMS'!$B$1:$B$200,"Julio Alejandro")+SUMIFS('Captura BMS'!$C$1:$C$200,'Captura BMS'!$A$1:$A$200,$A10,'Captura BMS'!$B$1:$B$200,"Procortes") | D10: =SUMIFS('Captura BMS'!$D$1:$D$200,'Captura BMS'!$A$1:$A$200,$A10,'Captura BMS'!$B$1:$B$200,"Julio Alejandro")+SUMIFS('Captura BMS'!$D$1:$D$200,'Captura BMS'!$A$1:$A$200,$A10,'Captura BMS'!$B$1:$B$200,"Procortes") | E10: =SUMIFS('Captura BMS'!$E$1:$E$200,'Captura BMS'!$A$1:$A$200,$A10,'Captura BMS'!$B$1:$B$200,"Julio Alejandro")+SUMIFS('Captura BMS'!$E$1:$E$200,'Captura BMS'!$A$1:$A$200,$A10,'Captura BMS'!$B$1:$B$200,"Procortes") | F10: =SUMIFS('Captura BMS'!$F$1:$F$200,'Captura BMS'!$A$1:$A$200,$A10,'Captura BMS'!$B$1:$B$200,"Julio Alejandro")+SUMIFS('Captura BMS'!$F$1:$F$200,'Captura BMS'!$A$1:$A$200,$A10,'Captura BMS'!$B$1:$B$200,"Procortes") | G10: =SUMIFS('Captura BMS'!$G$1:$G$200,'Captura BMS'!$A$1:$A$200,$A10,'Captura BMS'!$B$1:$B$200,"Julio Alejandro")+SUMIFS('Captura BMS'!$G$1:$G$200,'Captura BMS'!$A$1:$A$200,$A10,'Captura BMS'!$B$1:$B$200,"Procortes") | H10: =SUMIFS('Captura BMS'!$H$1:$H$200,'Captura BMS'!$A$1:$A$200,$A10,'Captura BMS'!$B$1:$B$200,"Julio Alejandro")+SUMIFS('Captura BMS'!$H$1:$H$200,'Captura BMS'!$A$1:$A$200,$A10,'Captura BMS'!$B$1:$B$200,"Procortes") | I10: =SUMIFS('Captura BMS'!$I$1:$I$200,'Captura BMS'!$A$1:$A$200,$A10,'Captura BMS'!$B$1:$B$200,"Julio Alejandro")+SUMIFS('Captura BMS'!$I$1:$I$200,'Captura BMS'!$A$1:$A$200,$A10,'Captura BMS'!$B$1:$B$200,"Procortes") | J10: =SUMIFS('Captura BMS'!$J$1:$J$200,'Captura BMS'!$A$1:$A$200,$A10,'Captura BMS'!$B$1:$B$200,"Julio Alejandro")+SUMIFS('Captura BMS'!$J$1:$J$200,'Captura BMS'!$A$1:$A$200,$A10,'Captura BMS'!$B$1:$B$200,"Procortes") | K10: =SUM(C10:J10) | L10: =IFERROR(AVERAGEIF(C10:J10,">0"),0) | M10: =IF(OR(C10=0,J10=0),"",J10/C10-1)
A11: Ixtapa | B11: — | C11: =SUMIFS('Captura BMS'!$C$1:$C$200,'Captura BMS'!$A$1:$A$200,$A11,'Captura BMS'!$B$1:$B$200,"Julio Alejandro")+SUMIFS('Captura BMS'!$C$1:$C$200,'Captura BMS'!$A$1:$A$200,$A11,'Captura BMS'!$B$1:$B$200,"Procortes") | D11: =SUMIFS('Captura BMS'!$D$1:$D$200,'Captura BMS'!$A$1:$A$200,$A11,'Captura BMS'!$B$1:$B$200,"Julio Alejandro")+SUMIFS('Captura BMS'!$D$1:$D$200,'Captura BMS'!$A$1:$A$200,$A11,'Captura BMS'!$B$1:$B$200,"Procortes") | E11: =SUMIFS('Captura BMS'!$E$1:$E$200,'Captura BMS'!$A$1:$A$200,$A11,'Captura BMS'!$B$1:$B$200,"Julio Alejandro")+SUMIFS('Captura BMS'!$E$1:$E$200,'Captura BMS'!$A$1:$A$200,$A11,'Captura BMS'!$B$1:$B$200,"Procortes") | F11: =SUMIFS('Captura BMS'!$F$1:$F$200,'Captura BMS'!$A$1:$A$200,$A11,'Captura BMS'!$B$1:$B$200,"Julio Alejandro")+SUMIFS('Captura BMS'!$F$1:$F$200,'Captura BMS'!$A$1:$A$200,$A11,'Captura BMS'!$B$1:$B$200,"Procortes") | G11: =SUMIFS('Captura BMS'!$G$1:$G$200,'Captura BMS'!$A$1:$A$200,$A11,'Captura BMS'!$B$1:$B$200,"Julio Alejandro")+SUMIFS('Captura BMS'!$G$1:$G$200,'Captura BMS'!$A$1:$A$200,$A11,'Captura BMS'!$B$1:$B$200,"Procortes") | H11: =SUMIFS('Captura BMS'!$H$1:$H$200,'Captura BMS'!$A$1:$A$200,$A11,'Captura BMS'!$B$1:$B$200,"Julio Alejandro")+SUMIFS('Captura BMS'!$H$1:$H$200,'Captura BMS'!$A$1:$A$200,$A11,'Captura BMS'!$B$1:$B$200,"Procortes") | I11: =SUMIFS('Captura BMS'!$I$1:$I$200,'Captura BMS'!$A$1:$A$200,$A11,'Captura BMS'!$B$1:$B$200,"Julio Alejandro")+SUMIFS('Captura BMS'!$I$1:$I$200,'Captura BMS'!$A$1:$A$200,$A11,'Captura BMS'!$B$1:$B$200,"Procortes") | J11: =SUMIFS('Captura BMS'!$J$1:$J$200,'Captura BMS'!$A$1:$A$200,$A11,'Captura BMS'!$B$1:$B$200,"Julio Alejandro")+SUMIFS('Captura BMS'!$J$1:$J$200,'Captura BMS'!$A$1:$A$200,$A11,'Captura BMS'!$B$1:$B$200,"Procortes") | K11: =SUM(C11:J11) | L11: =IFERROR(AVERAGEIF(C11:J11,">0"),0) | M11: =IF(OR(C11=0,J11=0),"",J11/C11-1)
A12: Ixtlán | B12: — | C12: =SUMIFS('Captura BMS'!$C$1:$C$200,'Captura BMS'!$A$1:$A$200,$A12,'Captura BMS'!$B$1:$B$200,"Julio Alejandro")+SUMIFS('Captura BMS'!$C$1:$C$200,'Captura BMS'!$A$1:$A$200,$A12,'Captura BMS'!$B$1:$B$200,"Procortes") | D12: =SUMIFS('Captura BMS'!$D$1:$D$200,'Captura BMS'!$A$1:$A$200,$A12,'Captura BMS'!$B$1:$B$200,"Julio Alejandro")+SUMIFS('Captura BMS'!$D$1:$D$200,'Captura BMS'!$A$1:$A$200,$A12,'Captura BMS'!$B$1:$B$200,"Procortes") | E12: =SUMIFS('Captura BMS'!$E$1:$E$200,'Captura BMS'!$A$1:$A$200,$A12,'Captura BMS'!$B$1:$B$200,"Julio Alejandro")+SUMIFS('Captura BMS'!$E$1:$E$200,'Captura BMS'!$A$1:$A$200,$A12,'Captura BMS'!$B$1:$B$200,"Procortes") | F12: =SUMIFS('Captura BMS'!$F$1:$F$200,'Captura BMS'!$A$1:$A$200,$A12,'Captura BMS'!$B$1:$B$200,"Julio Alejandro")+SUMIFS('Captura BMS'!$F$1:$F$200,'Captura BMS'!$A$1:$A$200,$A12,'Captura BMS'!$B$1:$B$200,"Procortes") | G12: =SUMIFS('Captura BMS'!$G$1:$G$200,'Captura BMS'!$A$1:$A$200,$A12,'Captura BMS'!$B$1:$B$200,"Julio Alejandro")+SUMIFS('Captura BMS'!$G$1:$G$200,'Captura BMS'!$A$1:$A$200,$A12,'Captura BMS'!$B$1:$B$200,"Procortes") | H12: =SUMIFS('Captura BMS'!$H$1:$H$200,'Captura BMS'!$A$1:$A$200,$A12,'Captura BMS'!$B$1:$B$200,"Julio Alejandro")+SUMIFS('Captura BMS'!$H$1:$H$200,'Captura BMS'!$A$1:$A$200,$A12,'Captura BMS'!$B$1:$B$200,"Procortes") | I12: =SUMIFS('Captura BMS'!$I$1:$I$200,'Captura BMS'!$A$1:$A$200,$A12,'Captura BMS'!$B$1:$B$200,"Julio Alejandro")+SUMIFS('Captura BMS'!$I$1:$I$200,'Captura BMS'!$A$1:$A$200,$A12,'Captura BMS'!$B$1:$B$200,"Procortes") | J12: =SUMIFS('Captura BMS'!$J$1:$J$200,'Captura BMS'!$A$1:$A$200,$A12,'Captura BMS'!$B$1:$B$200,"Julio Alejandro")+SUMIFS('Captura BMS'!$J$1:$J$200,'Captura BMS'!$A$1:$A$200,$A12,'Captura BMS'!$B$1:$B$200,"Procortes") | K12: =SUM(C12:J12) | L12: =IFERROR(AVERAGEIF(C12:J12,">0"),0) | M12: =IF(OR(C12=0,J12=0),"",J12/C12-1)
A13: Mezcales | B13: 28-sep-2026 | C13: =SUMIFS('Captura BMS'!$C$1:$C$200,'Captura BMS'!$A$1:$A$200,$A13,'Captura BMS'!$B$1:$B$200,"Julio Alejandro")+SUMIFS('Captura BMS'!$C$1:$C$200,'Captura BMS'!$A$1:$A$200,$A13,'Captura BMS'!$B$1:$B$200,"Procortes") | D13: =SUMIFS('Captura BMS'!$D$1:$D$200,'Captura BMS'!$A$1:$A$200,$A13,'Captura BMS'!$B$1:$B$200,"Julio Alejandro")+SUMIFS('Captura BMS'!$D$1:$D$200,'Captura BMS'!$A$1:$A$200,$A13,'Captura BMS'!$B$1:$B$200,"Procortes") | E13: =SUMIFS('Captura BMS'!$E$1:$E$200,'Captura BMS'!$A$1:$A$200,$A13,'Captura BMS'!$B$1:$B$200,"Julio Alejandro")+SUMIFS('Captura BMS'!$E$1:$E$200,'Captura BMS'!$A$1:$A$200,$A13,'Captura BMS'!$B$1:$B$200,"Procortes") | F13: =SUMIFS('Captura BMS'!$F$1:$F$200,'Captura BMS'!$A$1:$A$200,$A13,'Captura BMS'!$B$1:$B$200,"Julio Alejandro")+SUMIFS('Captura BMS'!$F$1:$F$200,'Captura BMS'!$A$1:$A$200,$A13,'Captura BMS'!$B$1:$B$200,"Procortes") | G13: =SUMIFS('Captura BMS'!$G$1:$G$200,'Captura BMS'!$A$1:$A$200,$A13,'Captura BMS'!$B$1:$B$200,"Julio Alejandro")+SUMIFS('Captura BMS'!$G$1:$G$200,'Captura BMS'!$A$1:$A$200,$A13,'Captura BMS'!$B$1:$B$200,"Procortes") | H13: =SUMIFS('Captura BMS'!$H$1:$H$200,'Captura BMS'!$A$1:$A$200,$A13,'Captura BMS'!$B$1:$B$200,"Julio Alejandro")+SUMIFS('Captura BMS'!$H$1:$H$200,'Captura BMS'!$A$1:$A$200,$A13,'Captura BMS'!$B$1:$B$200,"Procortes") | I13: =SUMIFS('Captura BMS'!$I$1:$I$200,'Captura BMS'!$A$1:$A$200,$A13,'Captura BMS'!$B$1:$B$200,"Julio Alejandro")+SUMIFS('Captura BMS'!$I$1:$I$200,'Captura BMS'!$A$1:$A$200,$A13,'Captura BMS'!$B$1:$B$200,"Procortes") | J13: =SUMIFS('Captura BMS'!$J$1:$J$200,'Captura BMS'!$A$1:$A$200,$A13,'Captura BMS'!$B$1:$B$200,"Julio Alejandro")+SUMIFS('Captura BMS'!$J$1:$J$200,'Captura BMS'!$A$1:$A$200,$A13,'Captura BMS'!$B$1:$B$200,"Procortes") | K13: =SUM(C13:J13) | L13: =IFERROR(AVERAGEIF(C13:J13,">0"),0) | M13: =IF(OR(C13=0,J13=0),"",J13/C13-1)
A14: Mojoneras | B14: — | C14: =SUMIFS('Captura BMS'!$C$1:$C$200,'Captura BMS'!$A$1:$A$200,$A14,'Captura BMS'!$B$1:$B$200,"Julio Alejandro")+SUMIFS('Captura BMS'!$C$1:$C$200,'Captura BMS'!$A$1:$A$200,$A14,'Captura BMS'!$B$1:$B$200,"Procortes") | D14: =SUMIFS('Captura BMS'!$D$1:$D$200,'Captura BMS'!$A$1:$A$200,$A14,'Captura BMS'!$B$1:$B$200,"Julio Alejandro")+SUMIFS('Captura BMS'!$D$1:$D$200,'Captura BMS'!$A$1:$A$200,$A14,'Captura BMS'!$B$1:$B$200,"Procortes") | E14: =SUMIFS('Captura BMS'!$E$1:$E$200,'Captura BMS'!$A$1:$A$200,$A14,'Captura BMS'!$B$1:$B$200,"Julio Alejandro")+SUMIFS('Captura BMS'!$E$1:$E$200,'Captura BMS'!$A$1:$A$200,$A14,'Captura BMS'!$B$1:$B$200,"Procortes") | F14: =SUMIFS('Captura BMS'!$F$1:$F$200,'Captura BMS'!$A$1:$A$200,$A14,'Captura BMS'!$B$1:$B$200,"Julio Alejandro")+SUMIFS('Captura BMS'!$F$1:$F$200,'Captura BMS'!$A$1:$A$200,$A14,'Captura BMS'!$B$1:$B$200,"Procortes") | G14: =SUMIFS('Captura BMS'!$G$1:$G$200,'Captura BMS'!$A$1:$A$200,$A14,'Captura BMS'!$B$1:$B$200,"Julio Alejandro")+SUMIFS('Captura BMS'!$G$1:$G$200,'Captura BMS'!$A$1:$A$200,$A14,'Captura BMS'!$B$1:$B$200,"Procortes") | H14: =SUMIFS('Captura BMS'!$H$1:$H$200,'Captura BMS'!$A$1:$A$200,$A14,'Captura BMS'!$B$1:$B$200,"Julio Alejandro")+SUMIFS('Captura BMS'!$H$1:$H$200,'Captura BMS'!$A$1:$A$200,$A14,'Captura BMS'!$B$1:$B$200,"Procortes") | I14: =SUMIFS('Captura BMS'!$I$1:$I$200,'Captura BMS'!$A$1:$A$200,$A14,'Captura BMS'!$B$1:$B$200,"Julio Alejandro")+SUMIFS('Captura BMS'!$I$1:$I$200,'Captura BMS'!$A$1:$A$200,$A14,'Captura BMS'!$B$1:$B$200,"Procortes") | J14: =SUMIFS('Captura BMS'!$J$1:$J$200,'Captura BMS'!$A$1:$A$200,$A14,'Captura BMS'!$B$1:$B$200,"Julio Alejandro")+SUMIFS('Captura BMS'!$J$1:$J$200,'Captura BMS'!$A$1:$A$200,$A14,'Captura BMS'!$B$1:$B$200,"Procortes") | K14: =SUM(C14:J14) | L14: =IFERROR(AVERAGEIF(C14:J14,">0"),0) | M14: =IF(OR(C14=0,J14=0),"",J14/C14-1)
A15: Nayarabastos | B15: — | C15: =SUMIFS('Captura BMS'!$C$1:$C$200,'Captura BMS'!$A$1:$A$200,$A15,'Captura BMS'!$B$1:$B$200,"Julio Alejandro")+SUMIFS('Captura BMS'!$C$1:$C$200,'Captura BMS'!$A$1:$A$200,$A15,'Captura BMS'!$B$1:$B$200,"Procortes") | D15: =SUMIFS('Captura BMS'!$D$1:$D$200,'Captura BMS'!$A$1:$A$200,$A15,'Captura BMS'!$B$1:$B$200,"Julio Alejandro")+SUMIFS('Captura BMS'!$D$1:$D$200,'Captura BMS'!$A$1:$A$200,$A15,'Captura BMS'!$B$1:$B$200,"Procortes") | E15: =SUMIFS('Captura BMS'!$E$1:$E$200,'Captura BMS'!$A$1:$A$200,$A15,'Captura BMS'!$B$1:$B$200,"Julio Alejandro")+SUMIFS('Captura BMS'!$E$1:$E$200,'Captura BMS'!$A$1:$A$200,$A15,'Captura BMS'!$B$1:$B$200,"Procortes") | F15: =SUMIFS('Captura BMS'!$F$1:$F$200,'Captura BMS'!$A$1:$A$200,$A15,'Captura BMS'!$B$1:$B$200,"Julio Alejandro")+SUMIFS('Captura BMS'!$F$1:$F$200,'Captura BMS'!$A$1:$A$200,$A15,'Captura BMS'!$B$1:$B$200,"Procortes") | G15: =SUMIFS('Captura BMS'!$G$1:$G$200,'Captura BMS'!$A$1:$A$200,$A15,'Captura BMS'!$B$1:$B$200,"Julio Alejandro")+SUMIFS('Captura BMS'!$G$1:$G$200,'Captura BMS'!$A$1:$A$200,$A15,'Captura BMS'!$B$1:$B$200,"Procortes") | H15: =SUMIFS('Captura BMS'!$H$1:$H$200,'Captura BMS'!$A$1:$A$200,$A15,'Captura BMS'!$B$1:$B$200,"Julio Alejandro")+SUMIFS('Captura BMS'!$H$1:$H$200,'Captura BMS'!$A$1:$A$200,$A15,'Captura BMS'!$B$1:$B$200,"Procortes") | I15: =SUMIFS('Captura BMS'!$I$1:$I$200,'Captura BMS'!$A$1:$A$200,$A15,'Captura BMS'!$B$1:$B$200,"Julio Alejandro")+SUMIFS('Captura BMS'!$I$1:$I$200,'Captura BMS'!$A$1:$A$200,$A15,'Captura BMS'!$B$1:$B$200,"Procortes") | J15: =SUMIFS('Captura BMS'!$J$1:$J$200,'Captura BMS'!$A$1:$A$200,$A15,'Captura BMS'!$B$1:$B$200,"Julio Alejandro")+SUMIFS('Captura BMS'!$J$1:$J$200,'Captura BMS'!$A$1:$A$200,$A15,'Captura BMS'!$B$1:$B$200,"Procortes") | K15: =SUM(C15:J15) | L15: =IFERROR(AVERAGEIF(C15:J15,">0"),0) | M15: =IF(OR(C15=0,J15=0),"",J15/C15-1)
A16: Peñita | B16: 14-sep-2026 | C16: =SUMIFS('Captura BMS'!$C$1:$C$200,'Captura BMS'!$A$1:$A$200,$A16,'Captura BMS'!$B$1:$B$200,"Julio Alejandro")+SUMIFS('Captura BMS'!$C$1:$C$200,'Captura BMS'!$A$1:$A$200,$A16,'Captura BMS'!$B$1:$B$200,"Procortes") | D16: =SUMIFS('Captura BMS'!$D$1:$D$200,'Captura BMS'!$A$1:$A$200,$A16,'Captura BMS'!$B$1:$B$200,"Julio Alejandro")+SUMIFS('Captura BMS'!$D$1:$D$200,'Captura BMS'!$A$1:$A$200,$A16,'Captura BMS'!$B$1:$B$200,"Procortes") | E16: =SUMIFS('Captura BMS'!$E$1:$E$200,'Captura BMS'!$A$1:$A$200,$A16,'Captura BMS'!$B$1:$B$200,"Julio Alejandro")+SUMIFS('Captura BMS'!$E$1:$E$200,'Captura BMS'!$A$1:$A$200,$A16,'Captura BMS'!$B$1:$B$200,"Procortes") | F16: =SUMIFS('Captura BMS'!$F$1:$F$200,'Captura BMS'!$A$1:$A$200,$A16,'Captura BMS'!$B$1:$B$200,"Julio Alejandro")+SUMIFS('Captura BMS'!$F$1:$F$200,'Captura BMS'!$A$1:$A$200,$A16,'Captura BMS'!$B$1:$B$200,"Procortes") | G16: =SUMIFS('Captura BMS'!$G$1:$G$200,'Captura BMS'!$A$1:$A$200,$A16,'Captura BMS'!$B$1:$B$200,"Julio Alejandro")+SUMIFS('Captura BMS'!$G$1:$G$200,'Captura BMS'!$A$1:$A$200,$A16,'Captura BMS'!$B$1:$B$200,"Procortes") | H16: =SUMIFS('Captura BMS'!$H$1:$H$200,'Captura BMS'!$A$1:$A$200,$A16,'Captura BMS'!$B$1:$B$200,"Julio Alejandro")+SUMIFS('Captura BMS'!$H$1:$H$200,'Captura BMS'!$A$1:$A$200,$A16,'Captura BMS'!$B$1:$B$200,"Procortes") | I16: =SUMIFS('Captura BMS'!$I$1:$I$200,'Captura BMS'!$A$1:$A$200,$A16,'Captura BMS'!$B$1:$B$200,"Julio Alejandro")+SUMIFS('Captura BMS'!$I$1:$I$200,'Captura BMS'!$A$1:$A$200,$A16,'Captura BMS'!$B$1:$B$200,"Procortes") | J16: =SUMIFS('Captura BMS'!$J$1:$J$200,'Captura BMS'!$A$1:$A$200,$A16,'Captura BMS'!$B$1:$B$200,"Julio Alejandro")+SUMIFS('Captura BMS'!$J$1:$J$200,'Captura BMS'!$A$1:$A$200,$A16,'Captura BMS'!$B$1:$B$200,"Procortes") | K16: =SUM(C16:J16) | L16: =IFERROR(AVERAGEIF(C16:J16,">0"),0) | M16: =IF(OR(C16=0,J16=0),"",J16/C16-1)
... A24: Xalisco | B24: 13-jul-2026 | C24: =SUMIFS('Captura BMS'!$C$1:$C$200,'Captura BMS'!$A$1:$A$200,$A24,'Captura BMS'!$B$1:$B$200,"Julio Alejandro")+SUMIFS('Captura BMS'!$C$1:$C$200,'Captura BMS'!$A$1:$A$200,$A24,'Captura BMS'!$B$1:$B$200,"Procortes") | D24: =SUMIFS('Captura BMS'!$D$1:$D$200,'Captura BMS'!$A$1:$A$200,$A24,'Captura BMS'!$B$1:$B$200,"Julio Alejandro")+SUMIFS('Captura BMS'!$D$1:$D$200,'Captura BMS'!$A$1:$A$200,$A24,'Captura BMS'!$B$1:$B$200,"Procortes") | E24: =SUMIFS('Captura BMS'!$E$1:$E$200,'Captura BMS'!$A$1:$A$200,$A24,'Captura BMS'!$B$1:$B$200,"Julio Alejandro")+SUMIFS('Captura BMS'!$E$1:$E$200,'Captura BMS'!$A$1:$A$200,$A24,'Captura BMS'!$B$1:$B$200,"Procortes") | F24: =SUMIFS('Captura BMS'!$F$1:$F$200,'Captura BMS'!$A$1:$A$200,$A24,'Captura BMS'!$B$1:$B$200,"Julio Alejandro")+SUMIFS('Captura BMS'!$F$1:$F$200,'Captura BMS'!$A$1:$A$200,$A24,'Captura BMS'!$B$1:$B$200,"Procortes") | G24: =SUMIFS('Captura BMS'!$G$1:$G$200,'Captura BMS'!$A$1:$A$200,$A24,'Captura BMS'!$B$1:$B$200,"Julio Alejandro")+SUMIFS('Captura BMS'!$G$1:$G$200,'Captura BMS'!$A$1:$A$200,$A24,'Captura BMS'!$B$1:$B$200,"Procortes") | H24: =SUMIFS('Captura BMS'!$H$1:$H$200,'Captura BMS'!$A$1:$A$200,$A24,'Captura BMS'!$B$1:$B$200,"Julio Alejandro")+SUMIFS('Captura BMS'!$H$1:$H$200,'Captura BMS'!$A$1:$A$200,$A24,'Captura BMS'!$B$1:$B$200,"Procortes") | I24: =SUMIFS('Captura BMS'!$I$1:$I$200,'Captura BMS'!$A$1:$A$200,$A24,'Captura BMS'!$B$1:$B$200,"Julio Alejandro")+SUMIFS('Captura BMS'!$I$1:$I$200,'Captura BMS'!$A$1:$A$200,$A24,'Captura BMS'!$B$1:$B$200,"Procortes") | J24: =SUMIFS('Captura BMS'!$J$1:$J$200,'Captura BMS'!$A$1:$A$200,$A24,'Captura BMS'!$B$1:$B$200,"Julio Alejandro")+SUMIFS('Captura BMS'!$J$1:$J$200,'Captura BMS'!$A$1:$A$200,$A24,'Captura BMS'!$B$1:$B$200,"Procortes") | K24: =SUM(C24:J24) | L24: =IFERROR(AVERAGEIF(C24:J24,">0"),0) | M24: =IF(OR(C24=0,J24=0),"",J24/C24-1)
A25: Subtotal tiendas JA / Procortes | C25: =SUM(C5:C24) | D25: =SUM(D5:D24) | E25: =SUM(E5:E24) | F25: =SUM(F5:F24) | G25: =SUM(G5:G24) | H25: =SUM(H5:H24) | I25: =SUM(I5:I24) | J25: =SUM(J5:J24) | K25: =SUM(C25:J25) | L25: =IFERROR(AVERAGEIF(C25:J25,">0"),0) | M25: =IF(OR(C25=0,J25=0),"",J25/C25-1)
A27: Juárez | B27: No aplica (Julián Aguillón) | C27: =SUMIFS('Captura BMS'!$C$1:$C$200,'Captura BMS'!$A$1:$A$200,$A27,'Captura BMS'!$B$1:$B$200,"Julián Aguillón") | D27: =SUMIFS('Captura BMS'!$D$1:$D$200,'Captura BMS'!$A$1:$A$200,$A27,'Captura BMS'!$B$1:$B$200,"Julián Aguillón") | E27: =SUMIFS('Captura BMS'!$E$1:$E$200,'Captura BMS'!$A$1:$A$200,$A27,'Captura BMS'!$B$1:$B$200,"Julián Aguillón") | F27: =SUMIFS('Captura BMS'!$F$1:$F$200,'Captura BMS'!$A$1:$A$200,$A27,'Captura BMS'!$B$1:$B$200,"Julián Aguillón") | G27: =SUMIFS('Captura BMS'!$G$1:$G$200,'Captura BMS'!$A$1:$A$200,$A27,'Captura BMS'!$B$1:$B$200,"Julián Aguillón") | H27: =SUMIFS('Captura BMS'!$H$1:$H$200,'Captura BMS'!$A$1:$A$200,$A27,'Captura BMS'!$B$1:$B$200,"Julián Aguillón") | I27: =SUMIFS('Captura BMS'!$I$1:$I$200,'Captura BMS'!$A$1:$A$200,$A27,'Captura BMS'!$B$1:$B$200,"Julián Aguillón") | J27: =SUMIFS('Captura BMS'!$J$1:$J$200,'Captura BMS'!$A$1:$A$200,$A27,'Captura BMS'!$B$1:$B$200,"Julián Aguillón") | K27: =SUM(C27:J27) | L27: =IFERROR(AVERAGEIF(C27:J27,">0"),0) | M27: =IF(OR(C27=0,J27=0),"",J27/C27-1)
A28: Real del Valle | B28: No aplica (Julián Aguillón) | C28: =SUMIFS('Captura BMS'!$C$1:$C$200,'Captura BMS'!$A$1:$A$200,$A28,'Captura BMS'!$B$1:$B$200,"Julián Aguillón") | D28: =SUMIFS('Captura BMS'!$D$1:$D$200,'Captura BMS'!$A$1:$A$200,$A28,'Captura BMS'!$B$1:$B$200,"Julián Aguillón") | E28: =SUMIFS('Captura BMS'!$E$1:$E$200,'Captura BMS'!$A$1:$A$200,$A28,'Captura BMS'!$B$1:$B$200,"Julián Aguillón") | F28: =SUMIFS('Captura BMS'!$F$1:$F$200,'Captura BMS'!$A$1:$A$200,$A28,'Captura BMS'!$B$1:$B$200,"Julián Aguillón") | G28: =SUMIFS('Captura BMS'!$G$1:$G$200,'Captura BMS'!$A$1:$A$200,$A28,'Captura BMS'!$B$1:$B$200,"Julián Aguillón") | H28: =SUMIFS('Captura BMS'!$H$1:$H$200,'Captura BMS'!$A$1:$A$200,$A28,'Captura BMS'!$B$1:$B$200,"Julián Aguillón") | I28: =SUMIFS('Captura BMS'!$I$1:$I$200,'Captura BMS'!$A$1:$A$200,$A28,'Captura BMS'!$B$1:$B$200,"Julián Aguillón") | J28: =SUMIFS('Captura BMS'!$J$1:$J$200,'Captura BMS'!$A$1:$A$200,$A28,'Captura BMS'!$B$1:$B$200,"Julián Aguillón") | K28: =SUM(C28:J28) | L28: =IFERROR(AVERAGEIF(C28:J28,">0"),0) | M28: =IF(OR(C28=0,J28=0),"",J28/C28-1)
A29: Parque Lineal | B29: No aplica (Julián Aguillón) | C29: =SUMIFS('Captura BMS'!$C$1:$C$200,'Captura BMS'!$A$1:$A$200,$A29,'Captura BMS'!$B$1:$B$200,"Julián Aguillón") | D29: =SUMIFS('Captura BMS'!$D$1:$D$200,'Captura BMS'!$A$1:$A$200,$A29,'Captura BMS'!$B$1:$B$200,"Julián Aguillón") | E29: =SUMIFS('Captura BMS'!$E$1:$E$200,'Captura BMS'!$A$1:$A$200,$A29,'Captura BMS'!$B$1:$B$200,"Julián Aguillón") | F29: =SUMIFS('Captura BMS'!$F$1:$F$200,'Captura BMS'!$A$1:$A$200,$A29,'Captura BMS'!$B$1:$B$200,"Julián Aguillón") | G29: =SUMIFS('Captura BMS'!$G$1:$G$200,'Captura BMS'!$A$1:$A$200,$A29,'Captura BMS'!$B$1:$B$200,"Julián Aguillón") | H29: =SUMIFS('Captura BMS'!$H$1:$H$200,'Captura BMS'!$A$1:$A$200,$A29,'Captura BMS'!$B$1:$B$200,"Julián Aguillón") | I29: =SUMIFS('Captura BMS'!$I$1:$I$200,'Captura BMS'!$A$1:$A$200,$A29,'Captura BMS'!$B$1:$B$200,"Julián Aguillón") | J29: =SUMIFS('Captura BMS'!$J$1:$J$200,'Captura BMS'!$A$1:$A$200,$A29,'Captura BMS'!$B$1:$B$200,"Julián Aguillón") | K29: =SUM(C29:J29) | L29: =IFERROR(AVERAGEIF(C29:J29,">0"),0) | M29: =IF(OR(C29=0,J29=0),"",J29/C29-1)
A30: Ejército | B30: No aplica (Julián Aguillón) | C30: =SUMIFS('Captura BMS'!$C$1:$C$200,'Captura BMS'!$A$1:$A$200,$A30,'Captura BMS'!$B$1:$B$200,"Julián Aguillón") | D30: =SUMIFS('Captura BMS'!$D$1:$D$200,'Captura BMS'!$A$1:$A$200,$A30,'Captura BMS'!$B$1:$B$200,"Julián Aguillón") | E30: =SUMIFS('Captura BMS'!$E$1:$E$200,'Captura BMS'!$A$1:$A$200,$A30,'Captura BMS'!$B$1:$B$200,"Julián Aguillón") | F30: =SUMIFS('Captura BMS'!$F$1:$F$200,'Captura BMS'!$A$1:$A$200,$A30,'Captura BMS'!$B$1:$B$200,"Julián Aguillón") | G30: =SUMIFS('Captura BMS'!$G$1:$G$200,'Captura BMS'!$A$1:$A$200,$A30,'Captura BMS'!$B$1:$B$200,"Julián Aguillón") | H30: =SUMIFS('Captura BMS'!$H$1:$H$200,'Captura BMS'!$A$1:$A$200,$A30,'Captura BMS'!$B$1:$B$200,"Julián Aguillón") | I30: =SUMIFS('Captura BMS'!$I$1:$I$200,'Captura BMS'!$A$1:$A$200,$A30,'Captura BMS'!$B$1:$B$200,"Julián Aguillón") | J30: =SUMIFS('Captura BMS'!$J$1:$J$200,'Captura BMS'!$A$1:$A$200,$A30,'Captura BMS'!$B$1:$B$200,"Julián Aguillón") | K30: =SUM(C30:J30) | L30: =IFERROR(AVERAGEIF(C30:J30,">0"),0) | M30: =IF(OR(C30=0,J30=0),"",J30/C30-1)
A31: Subtotal tiendas Julián Aguillón | C31: =SUM(C27:C30) | D31: =SUM(D27:D30) | E31: =SUM(E27:E30) | F31: =SUM(F27:F30) | G31: =SUM(G27:G30) | H31: =SUM(H27:H30) | I31: =SUM(I27:I30) | J31: =SUM(J27:J30) | K31: =SUM(C31:J31) | L31: =IFERROR(AVERAGEIF(C31:J31,">0"),0) | M31: =IF(OR(C31=0,J31=0),"",J31/C31-1)
A33: TOTAL GENERAL | C33: =C25+C31 | D33: =D25+D31 | E33: =E25+E31 | F33: =F25+F31 | G33: =G25+G31 | H33: =H25+H31 | I33: =I25+I31 | J33: =J25+J31 | K33: =SUM(C33:J33) | L33: =IFERROR(AVERAGEIF(C33:J33,">0"),0) | M33: =IF(OR(C33=0,J33=0),"",J33/C33-1)
A35: Notas
A36: 1. Feb–May: venta real BMS (hoja 'Ventas 2026' del archivo Proyectado 2026 Transicion Moral.xlsx). Jun–Sep: capturar desde cada BMS en la hoja 'Captura BMS'.
A37: 2. En el mes de migración la venta de la tienda está repartida entre los dos BMS: hay que sacar ambos reportes y se suman solos aquí.
A38: 3. Promedio mensual: solo cuenta meses con venta (Av. México abre en may; Ejército en mar).
A39: 4. Venta del CEDIS / SelectCarnes no incluida: es venta a tiendas, no al público (se duplicaría).
A40: 5. Octubre no se incluye (mes en curso). San Vicente (12-oct) y San José (19-oct) aún no migran en el periodo.

Sheet Captura BMS
A1: CAPTURA DE VENTA MENSUAL POR SUCURSAL — SALIDA DE CADA BMS (MXN, venta neta)
A2: Feb–May ya capturados (venta real). Llenar las celdas AMARILLAS con el reporte de venta por sucursal de cada BMS. GRIS = la sucursal no operó en esa razón ese mes. En el mes de migración se llenan AMBOS bloques (días antes y después del cambio).
A4: BMS JULIO ALEJANDRO
A5: Sucursal | B5: Razón / BMS | C5: Feb-26 | D5: Mar-26 | E5: Abr-26 | F5: May-26 | G5: Jun-26 | H5: Jul-26 | I5: Ago-26 | J5: Sep-26
A6: Av. México | B6: Julio Alejandro | F6: 8599487
A7: Bucerías | B7: Julio Alejandro | C7: 9498410 | D7: 10691253 | E7: 9944053 | F7: 10249459
A8: Cantera | B8: Julio Alejandro | C8: 5657163 | D8: 6260809 | E8: 6399045 | F8: 6689273
A9: Ejido | B9: Julio Alejandro | C9: 3290022 | D9: 3630575 | E9: 3706857 | F9: 3417909
A10: Fluvial | B10: Julio Alejandro | C10: 7157773 | D10: 8347204 | E10: 8296734 | F10: 8787142
A11: Insurgentes | B11: Julio Alejandro | C11: 6949647 | D11: 7671657
A12: Ixtapa | B12: Julio Alejandro | C12: 6803519 | D12: 7484529 | E12: 7568310 | F12: 8150094
A13: Ixtlán | B13: Julio Alejandro | C13: 3947110 | D13: 5366173 | E13: 5245363 | F13: 5324447
A14: Mezcales | B14: Julio Alejandro | C14: 9358821 | D14: 10464574 | E14: 10125025 | F14: 10112712
A15: Mojoneras | B15: Julio Alejandro | C15: 4790623 | D15: 5250213 | E15: 5112269 | F15: 5489332
A16: Nayarabastos | B16: Julio Alejandro | C16: 8626668 | D16: 9721925 | E16: 9732721 | F16: 11222302
A17: Peñita | B17: Julio Alejandro | C17: 7125778 | D17: 7885386 | E17: 8342868 | F17: 8305289
A18: Pitillal | B18: Julio Alejandro | C18: 8205197 | D18: 9304338 | E18: 9203270 | F18: 9752325
A19: Poetas | B19: Julio Alejandro | C19: 5585342 | D19: 6018431 | E19: 5760004 | F19: 6337713
A20: Romántica | B20: Julio Alejandro | C20: 6508140 | D20: 7132758 | E20: 7032010 | F20: 7048526
A21: San José | B21: Julio Alejandro | C21: 5654855 | D21: 6458709 | E21: 6411641 | F21: 7078464
A22: San Vicente | B22: Julio Alejandro | C22: 8161551 | D22: 8978260 | E22: 8801455 | F22: 9199558
A23: Santiago | B23: Julio Alejandro | C23: 4281614 | D23: 4563648 | E23: 4524040 | F23: 5196059
... A25: Xalisco | B25: Julio Alejandro | C25: 5020500 | D25: 5606021 | E25: 5823121 | F25: 6190939
A28: BMS PROCORTES
A29: Sucursal | B29: Razón / BMS | C29: Feb-26 | D29: Mar-26 | E29: Abr-26 | F29: May-26 | G29: Jun-26 | H29: Jul-26 | I29: Ago-26 | J29: Sep-26
A30: Av. México | B30: Procortes
A31: Bucerías | B31: Procortes
A32: Cantera | B32: Procortes
A33: Ejido | B33: Procortes
A34: Fluvial | B34: Procortes
A35: Insurgentes | B35: Procortes | E35: 7943756 | F35: 8012465
A36: Ixtapa | B36: Procortes
A37: Ixtlán | B37: Procortes
A38: Mezcales | B38: Procortes
A39: Mojoneras | B39: Procortes
A40: Nayarabastos | B40: Procortes
A41: Peñita | B41: Procortes
A42: Pitillal | B42: Procortes
A43: Poetas | B43: Procortes
A44: Romántica | B44: Procortes
...

Sheet Calendario migración
A1: Sucursal | B1: Inicio en Procortes | C1: Estatus de la fecha | D1: Meses del reporte en BMS Julio Alejandro | E1: Meses del reporte en BMS Procortes
A2: Insurgentes | B2: abr-2026 | C2: Ya operaba en Procortes en abril (dato BMS) | D2: Feb–Mar | E2: Abr–Sep
A3: Xalisco | B3: 13-jul-2026 | C3: Tentativa (calendario 13-jun) | D3: Feb–Jul (parcial) | E3: Jul (parcial)–Sep
A4: Cantera | B4: 27-jul-2026 | C4: Confirmada (correo 22-jul) | D4: Feb–Jul (parcial) | E4: Jul (parcial)–Sep
A5: Ejido | B5: 10-ago-2026 | C5: Confirmada (correo 06-ago) | D5: Feb–Ago (parcial) | E5: Ago (parcial)–Sep
A6: Av. México | B6: 17-ago-2026 | C6: Tentativa (calendario 13-jun) | D6: May–Ago (parcial) | E6: Ago (parcial)–Sep
A7: Villa Hidalgo | B7: 24-ago-2026 | C7: Tentativa (calendario 13-jun) | D7: Feb–Ago (parcial) | E7: Ago (parcial)–Sep
A8: Santiago | B8: 24-ago-2026 | C8: Tentativa (calendario 13-jun) | D8: Feb–Ago (parcial) | E8: Ago (parcial)–Sep
A9: Bucerías | B9: 07-sep-2026 | C9: Tentativa (seguimiento 02-sep) | D9: Feb–Sep (parcial) | E9: Sep (parcial)
A10: Peñita | B10: 14-sep-2026 | C10: Confirmada (correo 10-sep) | D10: Feb–Sep (parcial) | E10: Sep (parcial)
A11: Mezcales | B11: 28-sep-2026 | C11: Confirmada (correo 26-sep) | D11: Feb–Sep (parcial) | E11: Sep (parcial)
A12: San Vicente | B12: 12-oct-2026 | C12: Fuera del periodo (todo en BMS Julio Alejandro) | D12: Feb–Sep | E12: —
A13: San José | B13: 19-oct-2026 | C13: Fuera del periodo (todo en BMS Julio Alejandro) | D13: Feb–Sep | E13: —
A15: Fuente: correos de Citlali Amaya (Transición a Persona Moral). Las fechas 'Tentativa' vienen del calendario del 13-jun; confirmar en BMS Procortes la fecha del primer ticket.
